Workbook

Sheet Cover
A1: TestCo Industries — DCF Valuation
A3: Color legend
A4: Blue text | B4: hardcoded input (Assumptions only)
A5: Black text | B5: formula
A6: Green text | B6: cross-sheet link
A7: Yellow background | B7: key cells / CMP / 20% IRR row
A9: VALUATION SUMMARY
A10: Metric | B10: Bear | C10: Base | D10: Bull
A11: Revenue (FY35) | B11: ='DCF'!$M$7 | C11: ='DCF'!$M$8 | D11: ='DCF'!$M$9
A12: EBITDA (FY35) | B12: ='DCF'!$M$21 | C12: ='DCF'!$M$24 | D12: ='DCF'!$M$27
A13: FCFF (FY35) | B13: ='DCF'!$M$42 | C13: ='DCF'!$M$57 | D13: ='DCF'!$M$72
A14: Sum PV(FCFFs) | B14: ='DCF'!$B$89 | C14: ='DCF'!$C$89 | D14: ='DCF'!$D$89
A15: Terminal Value | B15: ='DCF'!$B$91 | C15: ='DCF'!$C$91 | D15: ='DCF'!$D$91
A16: Enterprise Value | B16: ='DCF'!$B$93 | C16: ='DCF'!$C$93 | D16: ='DCF'!$D$93
A17: Equity Value | B17: ='DCF'!$B$95 | C17: ='DCF'!$C$95 | D17: ='DCF'!$D$95
A18: Implied Price per Share | B18: ='DCF'!$B$97 | C18: ='DCF'!$C$97 | D18: ='DCF'!$D$97
A19: CMP | B19: ='Assumptions'!$B$8 | C19: ='Assumptions'!$B$8 | D19: ='Assumptions'!$B$8
A20: Upside vs CMP | B20: ='DCF'!$B$99 | C20: ='DCF'!$C$99 | D20: ='DCF'!$D$99
A22: KEY OBSERVATIONS
A23: • Base case implies modest upside vs CMP; high sensitivity to WACC
A24: • Multiple-based exit yields wider range vs DCF intrinsic
A25: • Reverse DCF: implied TGR exceeds Base — market pricing in stronger growth
A27: ESTIMATED INPUTS (flagged)
A28: • beta: ESTIMATED — basis: 2y weekly regression on Yahoo data

Sheet Assumptions
A1: ASSUMPTIONS — TestCo Industries
A3: COMPANY
A4: Company name | B4: TestCo Industries
A5: Ticker | B5: TESTCO.NS
A6: Currency | B6: INR
A7: FY end | B7: Mar
A8: Current Market Price (CMP) | B8: 1500
A9: Diluted shares outstanding (mn) | B9: 100
A10: Net cash (Cash − Debt) | B10: -5000
A12: WACC BUILD
A13: Component | B13: Value | H13: Source / Rationale
A14: Risk-free rate (Rf, 10y govt bond) | B14: 0.071 | H14: Rf: 10y G-Sec; ERP: Damodaran India Jul-26
A15: Equity risk premium (ERP, Damodaran) | B15: 0.075
A16: Beta (2y weekly vs benchmark) | B16: 1.1
A17: Cost of equity (Ke = Rf + β × ERP) | B17: =B14+B16*B15
A18: Cost of debt (Kd, pre-tax) | B18: 0.085
A19: Tax rate | B19: 0.252
A20: Kd after-tax = Kd × (1 − T) | B20: =B18*(1-B19)
A21: Equity weight | B21: 0.85
A22: Debt weight = 1 − Equity weight | B22: =1-B21
A23: WACC = Ke × wₑ + Kd_AT × w_d | B23: =B17*B21+B20*B22
A25: SCENARIO ASSUMPTIONS
A26: Driver | B26: Bear | C26: Base | D26: Bull | H26: Rationale
A27: Revenue CAGR Phase 1 (FY26–FY30) | B27: 0.07 | C27: 0.12 | D27: 0.18 | H27: Mgmt guidance: revenue 12-14% CAGR
A28: Revenue CAGR Phase 2 (FY31–FY35) | B28: 0.04 | C28: 0.07 | D28: 0.1
A29: EBITDA margin (terminal year) | B29: 0.16 | C29: 0.2 | D29: 0.24
A30: Tax rate (steady-state) | B30: 0.252 | C30: 0.252 | D30: 0.252
A31: Capex % of revenue | B31: 0.045 | C31: 0.04 | D31: 0.038
A32: D&A % of revenue | B32: 0.03 | C32: 0.03 | D32: 0.03
A33: ΔNWC % of revenue | B33: 0.02 | C33: 0.02 | D33: 0.02
A34: Terminal growth rate (TGR) | B34: 0.03 | C34: 0.04 | D34: 0.05
A36: HISTORICAL ACTUALS
A37: Line item | B37: FY23 | C37: FY24 | H37: Source
A38: Revenue | B38: 50000 | C38: 58000
A39: EBITDA | B39: 9000 | C39: 11000
A40: D&A | B40: 1500 | C40: 1700
A41: Capex | B41: 2200 | C41: 2400
A42: ΔNWC | B42: 800 | C42: 950
A43: Effective tax rate | B43: 0.252 | C43: 0.248
A45: PEER COMPS
...

Sheet DCF
A1: DCF MODEL — TestCo Industries
A3: § 1 REVENUE BUILD
A4: Year | B4: FY23A | C4: FY24A | D4: FY26E | E4: FY27E | F4: FY28E | G4: FY29E | H4: FY30E | I4: FY31E | J4: FY32E | K4: FY33E | L4: FY34E | M4: FY35E
A5: Revenue (historical) | B5: ='Assumptions'!$B$38 | C5: ='Assumptions'!$C$38
A7: Revenue — Bear | B7: =B5 | C7: =C5 | D7: =C7*(1+'Assumptions'!$B$27) | E7: =D7*(1+'Assumptions'!$B$27) | F7: =E7*(1+'Assumptions'!$B$27) | G7: =F7*(1+'Assumptions'!$B$27) | H7: =G7*(1+'Assumptions'!$B$27) | I7: =H7*(1+'Assumptions'!$B$28) | J7: =I7*(1+'Assumptions'!$B$28) | K7: =J7*(1+'Assumptions'!$B$28) | L7: =K7*(1+'Assumptions'!$B$28) | M7: =L7*(1+'Assumptions'!$B$28)
A8: Revenue — Base | B8: =B5 | C8: =C5 | D8: =C8*(1+'Assumptions'!$C$27) | E8: =D8*(1+'Assumptions'!$C$27) | F8: =E8*(1+'Assumptions'!$C$27) | G8: =F8*(1+'Assumptions'!$C$27) | H8: =G8*(1+'Assumptions'!$C$27) | I8: =H8*(1+'Assumptions'!$C$28) | J8: =I8*(1+'Assumptions'!$C$28) | K8: =J8*(1+'Assumptions'!$C$28) | L8: =K8*(1+'Assumptions'!$C$28) | M8: =L8*(1+'Assumptions'!$C$28)
A9: Revenue — Bull | B9: =B5 | C9: =C5 | D9: =C9*(1+'Assumptions'!$D$27) | E9: =D9*(1+'Assumptions'!$D$27) | F9: =E9*(1+'Assumptions'!$D$27) | G9: =F9*(1+'Assumptions'!$D$27) | H9: =G9*(1+'Assumptions'!$D$27) | I9: =H9*(1+'Assumptions'!$D$28) | J9: =I9*(1+'Assumptions'!$D$28) | K9: =J9*(1+'Assumptions'!$D$28) | L9: =K9*(1+'Assumptions'!$D$28) | M9: =L9*(1+'Assumptions'!$D$28)
A11: growth % — Bear | D11: =D7/C7-1 | E11: =E7/D7-1 | F11: =F7/E7-1 | G11: =G7/F7-1 | H11: =H7/G7-1 | I11: =I7/H7-1 | J11: =J7/I7-1 | K11: =K7/J7-1 | ... M11: =M7/L7-1
A12: growth % — Base | D12: =D8/C8-1 | E12: =E8/D8-1 | F12: =F8/E8-1 | G12: =G8/F8-1 | H12: =H8/G8-1 | I12: =I8/H8-1 | J12: =J8/I8-1 | K12: =K8/J8-1 | ... M12: =M8/L8-1
A13: growth % — Bull | D13: =D9/C9-1 | E13: =E9/D9-1 | F13: =F9/E9-1 | G13: =G9/F9-1 | H13: =H9/G9-1 | I13: =I9/H9-1 | J13: =J9/I9-1 | K13: =K9/J9-1 | ... M13: =M9/L9-1
A15: § 2 EBITDA & COST WATERFALL
A16: Year | B16: FY23A | C16: FY24A | D16: FY26E | E16: FY27E | F16: FY28E | G16: FY29E | H16: FY30E | I16: FY31E | J16: FY32E | K16: FY33E | L16: FY34E | M16: FY35E
A17: EBITDA (historical) | B17: ='Assumptions'!$B$39 | C17: ='Assumptions'!$C$39
A18: EBITDA margin (historical) | B18: =B17/B5 | C18: =C17/C5
A20: EBITDA margin — Bear | B20: =B17/B5 | C20: =C17/C5 | D20: =C20+('Assumptions'!$B$29-C20)*1/10 | E20: =C20+('Assumptions'!$B$29-C20)*2/10 | F20: =C20+('Assumptions'!$B$29-C20)*3/10 | G20: =C20+('Assumptions'!$B$29-C20)*4/10 | H20: =C20+('Assumptions'!$B$29-C20)*5/10 | I20: =C20+('Assumptions'!$B$29-C20)*6/10 | J20: =C20+('Assumptions'!$B$29-C20)*7/10 | K20: =C20+('Assumptions'!$B$29-C20)*8/10 | L20: =C20+('Assumptions'!$B$29-C20)*9/10 | M20: =C20+('Assumptions'!$B$29-C20)*10/10
A21: EBITDA — Bear | B21: =B17 | C21: =C17 | D21: =D7*D20 | E21: =E7*E20 | F21: =F7*F20 | G21: =G7*G20 | H21: =H7*H20 | I21: =I7*I20 | J21: =J7*J20 | K21: =K7*K20 | ... M21: =M7*M20
A23: EBITDA margin — Base | B23: =B17/B5 | C23: =C17/C5 | D23: =C23+('Assumptions'!$C$29-C23)*1/10 | E23: =C23+('Assumptions'!$C$29-C23)*2/10 | F23: =C23+('Assumptions'!$C$29-C23)*3/10 | G23: =C23+('Assumptions'!$C$29-C23)*4/10 | H23: =C23+('Assumptions'!$C$29-C23)*5/10 | I23: =C23+('Assumptions'!$C$29-C23)*6/10 | J23: =C23+('Assumptions'!$C$29-C23)*7/10 | K23: =C23+('Assumptions'!$C$29-C23)*8/10 | L23: =C23+('Assumptions'!$C$29-C23)*9/10 | M23: =C23+('Assumptions'!$C$29-C23)*10/10
A24: EBITDA — Base | B24: =B17 | C24: =C17 | D24: =D8*D23 | E24: =E8*E23 | F24: =F8*F23 | G24: =G8*G23 | H24: =H8*H23 | I24: =I8*I23 | J24: =J8*J23 | K24: =K8*K23 | ... M24: =M8*M23
A26: EBITDA margin — Bull | B26: =B17/B5 | C26: =C17/C5 | D26: =C26+('Assumptions'!$D$29-C26)*1/10 | E26: =C26+('Assumptions'!$D$29-C26)*2/10 | F26: =C26+('Assumptions'!$D$29-C26)*3/10 | G26: =C26+('Assumptions'!$D$29-C26)*4/10 | H26: =C26+('Assumptions'!$D$29-C26)*5/10 | I26: =C26+('Assumptions'!$D$29-C26)*6/10 | J26: =C26+('Assumptions'!$D$29-C26)*7/10 | K26: =C26+('Assumptions'!$D$29-C26)*8/10 | L26: =C26+('Assumptions'!$D$29-C26)*9/10 | M26: =C26+('Assumptions'!$D$29-C26)*10/10
A27: EBITDA — Bull | B27: =B17 | C27: =C17 | D27: =D9*D26 | E27: =E9*E26 | F27: =F9*F26 | G27: =G9*G26 | H27: =H9*H26 | I27: =I9*I26 | J27: =J9*J26 | K27: =K9*K26 | ... M27: =M9*M26
A30: § 3 FCFF BRIDGE (per scenario)
A31: ▸ BEAR CASE
A32: Year | B32: FY23A | C32: FY24A | D32: FY26E | E32: FY27E | F32: FY28E | G32: FY29E | H32: FY30E | I32: FY31E | J32: FY32E | K32: FY33E | L32: FY34E | M32: FY35E
A33: Year # | B33: — | C33: — | D33: 1 | E33: 2 | F33: 3 | G33: 4 | H33: 5 | I33: 6 | J33: 7 | K33: 8 | L33: 9 | M33: 10
A34: EBITDA | B34: =B21 | C34: =C21 | D34: =D21 | E34: =E21 | F34: =F21 | G34: =G21 | H34: =H21 | I34: =I21 | ... M34: =M21
A35: − D&A | B35: =-'Assumptions'!$B$40 | C35: =-'Assumptions'!$C$40 | D35: =-D7*'Assumptions'!$B$32 | E35: =-E7*'Assumptions'!$B$32 | F35: =-F7*'Assumptions'!$B$32 | G35: =-G7*'Assumptions'!$B$32 | H35: =-H7*'Assumptions'!$B$32 | I35: =-I7*'Assumptions'!$B$32 | J35: =-J7*'Assumptions'!$B$32 | K35: =-K7*'Assumptions'!$B$32 | ... M35: =-M7*'Assumptions'!$B$32
A36: EBIT | B36: =B34+B35 | C36: =C34+C35 | D36: =D34+D35 | E36: =E34+E35 | F36: =F34+F35 | G36: =G34+G35 | H36: =H34+H35 | I36: =I34+I35 | ... M36: =M34+M35
A37: − Tax | B37: =-B36*'Assumptions'!$B$43 | C37: =-C36*'Assumptions'!$C$43 | D37: =-MAX(D36,0)*'Assumptions'!$B$30 | E37: =-MAX(E36,0)*'Assumptions'!$B$30 | F37: =-MAX(F36,0)*'Assumptions'!$B$30 | G37: =-MAX(G36,0)*'Assumptions'!$B$30 | H37: =-MAX(H36,0)*'Assumptions'!$B$30 | I37: =-MAX(I36,0)*'Assumptions'!$B$30 | J37: =-MAX(J36,0)*'Assumptions'!$B$30 | K37: =-MAX(K36,0)*'Assumptions'!$B$30 | ... M37: =-MAX(M36,0)*'Assumptions'!$B$30
A38: NOPAT | B38: =B36+B37 | C38: =C36+C37 | D38: =D36+D37 | E38: =E36+E37 | F38: =F36+F37 | G38: =G36+G37 | H38: =H36+H37 | I38: =I36+I37 | ... M38: =M36+M37
A39: + D&A (add back) | B39: =-B35 | C39: =-C35 | D39: =-D35 | E39: =-E35 | F39: =-F35 | G39: =-G35 | H39: =-H35 | I39: =-I35 | ... M39: =-M35
A40: − Capex | B40: =-'Assumptions'!$B$41 | C40: =-'Assumptions'!$C$41 | D40: =-D7*'Assumptions'!$B$31 | E40: =-E7*'Assumptions'!$B$31 | F40: =-F7*'Assumptions'!$B$31 | G40: =-G7*'Assumptions'!$B$31 | H40: =-H7*'Assumptions'!$B$31 | I40: =-I7*'Assumptions'!$B$31 | J40: =-J7*'Assumptions'!$B$31 | K40: =-K7*'Assumptions'!$B$31 | ... M40: =-M7*'Assumptions'!$B$31
A41: − ΔNWC | B41: =-'Assumptions'!$B$42 | C41: =-'Assumptions'!$C$42 | D41: =-D7*'Assumptions'!$B$33 | E41: =-E7*'Assumptions'!$B$33 | F41: =-F7*'Assumptions'!$B$33 | G41: =-G7*'Assumptions'!$B$33 | H41: =-H7*'Assumptions'!$B$33 | I41: =-I7*'Assumptions'!$B$33 | J41: =-J7*'Assumptions'!$B$33 | K41: =-K7*'Assumptions'!$B$33 | ... M41: =-M7*'Assumptions'!$B$33
A42: FCFF | B42: =B38+B39+B40+B41 | C42: =C38+C39+C40+C41 | D42: =D38+D39+D40+D41 | E42: =E38+E39+E40+E41 | F42: =F38+F39+F40+F41 | G42: =G38+G39+G40+G41 | H42: =H38+H39+H40+H41 | I42: =I38+I39+I40+I41 | ... M42: =M38+M39+M40+M41
A43: Discount factor | B43: — | C43: — | D43: =1/((1+'Assumptions'!$B$23)^D33) | E43: =1/((1+'Assumptions'!$B$23)^E33) | F43: =1/((1+'Assumptions'!$B$23)^F33) | G43: =1/((1+'Assumptions'!$B$23)^G33) | H43: =1/((1+'Assumptions'!$B$23)^H33) | I43: =1/((1+'Assumptions'!$B$23)^I33) | J43: =1/((1+'Assumptions'!$B$23)^J33) | K43: =1/((1+'Assumptions'!$B$23)^K33) | ... M43: =1/((1+'Assumptions'!$B$23)^M33)
A44: PV of FCFF | B44: — | C44: — | D44: =D42*D43 | E44: =E42*E43 | F44: =F42*F43 | G44: =G42*G43 | H44: =H42*H43 | I44: =I42*I43 | J44: =J42*J43 | K44: =K42*K43 | ... M44: =M42*M43
A46: ▸ BASE CASE
A47: Year | B47: FY23A | C47: FY24A | D47: FY26E | E47: FY27E | F47: FY28E | G47: FY29E | H47: FY30E | I47: FY31E | J47: FY32E | K47: FY33E | L47: FY34E | M47: FY35E
A48: Year # | B48: — | C48: — | D48: 1 | E48: 2 | F48: 3 | G48: 4 | H48: 5 | I48: 6 | J48: 7 | K48: 8 | L48: 9 | M48: 10
A49: EBITDA | B49: =B24 | C49: =C24 | D49: =D24 | E49: =E24 | F49: =F24 | G49: =G24 | H49: =H24 | I49: =I24 | ... M49: =M24
A50: − D&A | B50: =-'Assumptions'!$B$40 | C50: =-'Assumptions'!$C$40 | D50: =-D8*'Assumptions'!$C$32 | E50: =-E8*'Assumptions'!$C$32 | F50: =-F8*'Assumptions'!$C$32 | G50: =-G8*'Assumptions'!$C$32 | H50: =-H8*'Assumptions'!$C$32 | I50: =-I8*'Assumptions'!$C$32 | J50: =-J8*'Assumptions'!$C$32 | K50: =-K8*'Assumptions'!$C$32 | ... M50: =-M8*'Assumptions'!$C$32
...

Sheet Returns_DCF
A1: RETURNS — DCF Intrinsic (exit = DCF intrinsic value only)
A3: Approach: A — DCF Intrinsic
A4: Exit prices from DCF intrinsic value only; no market multiple applied.
A6: ▸ BEAR CASE
A7: Entry price ↓ / Holding period → | B7: 3 yr | C7: 5 yr | D7: 7 yr | E7: 10 yr | F7: Exit price (DCF intrinsic)
A8: ='Assumptions'!$B$8*(1+-0.3) | B8: =('DCF'!$B$97/A8)^(1/3)-1 | C8: =('DCF'!$B$97/A8)^(1/5)-1 | D8: =('DCF'!$B$97/A8)^(1/7)-1 | E8: =('DCF'!$B$97/A8)^(1/10)-1 | F8: ='DCF'!$B$97
A9: ='Assumptions'!$B$8*(1+-0.2) | B9: =('DCF'!$B$97/A9)^(1/3)-1 | C9: =('DCF'!$B$97/A9)^(1/5)-1 | D9: =('DCF'!$B$97/A9)^(1/7)-1 | E9: =('DCF'!$B$97/A9)^(1/10)-1 | F9: ='DCF'!$B$97
A10: ='Assumptions'!$B$8*(1+-0.1) | B10: =('DCF'!$B$97/A10)^(1/3)-1 | C10: =('DCF'!$B$97/A10)^(1/5)-1 | D10: =('DCF'!$B$97/A10)^(1/7)-1 | E10: =('DCF'!$B$97/A10)^(1/10)-1 | F10: ='DCF'!$B$97
A11: ='Assumptions'!$B$8*(1+0.0) | B11: =('DCF'!$B$97/A11)^(1/3)-1 | C11: =('DCF'!$B$97/A11)^(1/5)-1 | D11: =('DCF'!$B$97/A11)^(1/7)-1 | E11: =('DCF'!$B$97/A11)^(1/10)-1 | F11: ='DCF'!$B$97
A12: ='Assumptions'!$B$8*(1+0.1) | B12: =('DCF'!$B$97/A12)^(1/3)-1 | C12: =('DCF'!$B$97/A12)^(1/5)-1 | D12: =('DCF'!$B$97/A12)^(1/7)-1 | E12: =('DCF'!$B$97/A12)^(1/10)-1 | F12: ='DCF'!$B$97
A13: ='Assumptions'!$B$8*(1+0.2) | B13: =('DCF'!$B$97/A13)^(1/3)-1 | C13: =('DCF'!$B$97/A13)^(1/5)-1 | D13: =('DCF'!$B$97/A13)^(1/7)-1 | E13: =('DCF'!$B$97/A13)^(1/10)-1 | F13: ='DCF'!$B$97
A14: ='Assumptions'!$B$8*(1+0.3) | B14: =('DCF'!$B$97/A14)^(1/3)-1 | C14: =('DCF'!$B$97/A14)^(1/5)-1 | D14: =('DCF'!$B$97/A14)^(1/7)-1 | E14: =('DCF'!$B$97/A14)^(1/10)-1 | F14: ='DCF'!$B$97
A16: Max entry for target IRR | B16: 3 yr | C16: 5 yr | D16: 7 yr | E16: 10 yr
A17: 10% IRR target | B17: ='DCF'!$B$97/(1+0.1)^3 | C17: ='DCF'!$B$97/(1+0.1)^5 | D17: ='DCF'!$B$97/(1+0.1)^7 | E17: ='DCF'!$B$97/(1+0.1)^10
A18: 15% IRR target | B18: ='DCF'!$B$97/(1+0.15)^3 | C18: ='DCF'!$B$97/(1+0.15)^5 | D18: ='DCF'!$B$97/(1+0.15)^7 | E18: ='DCF'!$B$97/(1+0.15)^10
A19: 20% IRR target | B19: ='DCF'!$B$97/(1+0.2)^3 | C19: ='DCF'!$B$97/(1+0.2)^5 | D19: ='DCF'!$B$97/(1+0.2)^7 | E19: ='DCF'!$B$97/(1+0.2)^10
A20: 25% IRR target | B20: ='DCF'!$B$97/(1+0.25)^3 | C20: ='DCF'!$B$97/(1+0.25)^5 | D20: ='DCF'!$B$97/(1+0.25)^7 | E20: ='DCF'!$B$97/(1+0.25)^10
A21: 30% IRR target | B21: ='DCF'!$B$97/(1+0.3)^3 | C21: ='DCF'!$B$97/(1+0.3)^5 | D21: ='DCF'!$B$97/(1+0.3)^7 | E21: ='DCF'!$B$97/(1+0.3)^10
A24: ▸ BASE CASE
A25: Entry price ↓ / Holding period → | B25: 3 yr | C25: 5 yr | D25: 7 yr | E25: 10 yr | F25: Exit price (DCF intrinsic)
A26: ='Assumptions'!$B$8*(1+-0.3) | B26: =('DCF'!$C$97/A26)^(1/3)-1 | C26: =('DCF'!$C$97/A26)^(1/5)-1 | D26: =('DCF'!$C$97/A26)^(1/7)-1 | E26: =('DCF'!$C$97/A26)^(1/10)-1 | F26: ='DCF'!$C$97
A27: ='Assumptions'!$B$8*(1+-0.2) | B27: =('DCF'!$C$97/A27)^(1/3)-1 | C27: =('DCF'!$C$97/A27)^(1/5)-1 | D27: =('DCF'!$C$97/A27)^(1/7)-1 | E27: =('DCF'!$C$97/A27)^(1/10)-1 | F27: ='DCF'!$C$97
A28: ='Assumptions'!$B$8*(1+-0.1) | B28: =('DCF'!$C$97/A28)^(1/3)-1 | C28: =('DCF'!$C$97/A28)^(1/5)-1 | D28: =('DCF'!$C$97/A28)^(1/7)-1 | E28: =('DCF'!$C$97/A28)^(1/10)-1 | F28: ='DCF'!$C$97
A29: ='Assumptions'!$B$8*(1+0.0) | B29: =('DCF'!$C$97/A29)^(1/3)-1 | C29: =('DCF'!$C$97/A29)^(1/5)-1 | D29: =('DCF'!$C$97/A29)^(1/7)-1 | E29: =('DCF'!$C$97/A29)^(1/10)-1 | F29: ='DCF'!$C$97
A30: ='Assumptions'!$B$8*(1+0.1) | B30: =('DCF'!$C$97/A30)^(1/3)-1 | C30: =('DCF'!$C$97/A30)^(1/5)-1 | D30: =('DCF'!$C$97/A30)^(1/7)-1 | E30: =('DCF'!$C$97/A30)^(1/10)-1 | F30: ='DCF'!$C$97
A31: ='Assumptions'!$B$8*(1+0.2) | B31: =('DCF'!$C$97/A31)^(1/3)-1 | C31: =('DCF'!$C$97/A31)^(1/5)-1 | D31: =('DCF'!$C$97/A31)^(1/7)-1 | E31: =('DCF'!$C$97/A31)^(1/10)-1 | F31: ='DCF'!$C$97
A32: ='Assumptions'!$B$8*(1+0.3) | B32: =('DCF'!$C$97/A32)^(1/3)-1 | C32: =('DCF'!$C$97/A32)^(1/5)-1 | D32: =('DCF'!$C$97/A32)^(1/7)-1 | E32: =('DCF'!$C$97/A32)^(1/10)-1 | F32: ='DCF'!$C$97
A34: Max entry for target IRR | B34: 3 yr | C34: 5 yr | D34: 7 yr | E34: 10 yr
A35: 10% IRR target | B35: ='DCF'!$C$97/(1+0.1)^3 | C35: ='DCF'!$C$97/(1+0.1)^5 | D35: ='DCF'!$C$97/(1+0.1)^7 | E35: ='DCF'!$C$97/(1+0.1)^10
A36: 15% IRR target | B36: ='DCF'!$C$97/(1+0.15)^3 | C36: ='DCF'!$C$97/(1+0.15)^5 | D36: ='DCF'!$C$97/(1+0.15)^7 | E36: ='DCF'!$C$97/(1+0.15)^10
A37: 20% IRR target | B37: ='DCF'!$C$97/(1+0.2)^3 | C37: ='DCF'!$C$97/(1+0.2)^5 | D37: ='DCF'!$C$97/(1+0.2)^7 | E37: ='DCF'!$C$97/(1+0.2)^10
A38: 25% IRR target | B38: ='DCF'!$C$97/(1+0.25)^3 | C38: ='DCF'!$C$97/(1+0.25)^5 | D38: ='DCF'!$C$97/(1+0.25)^7 | E38: ='DCF'!$C$97/(1+0.25)^10
A39: 30% IRR target | B39: ='DCF'!$C$97/(1+0.3)^3 | C39: ='DCF'!$C$97/(1+0.3)^5 | D39: ='DCF'!$C$97/(1+0.3)^7 | E39: ='DCF'!$C$97/(1+0.3)^10
A42: ▸ BULL CASE
A43: Entry price ↓ / Holding period → | B43: 3 yr | C43: 5 yr | D43: 7 yr | E43: 10 yr | F43: Exit price (DCF intrinsic)
A44: ='Assumptions'!$B$8*(1+-0.3) | B44: =('DCF'!$D$97/A44)^(1/3)-1 | C44: =('DCF'!$D$97/A44)^(1/5)-1 | D44: =('DCF'!$D$97/A44)^(1/7)-1 | E44: =('DCF'!$D$97/A44)^(1/10)-1 | F44: ='DCF'!$D$97
A45: ='Assumptions'!$B$8*(1+-0.2) | B45: =('DCF'!$D$97/A45)^(1/3)-1 | C45: =('DCF'!$D$97/A45)^(1/5)-1 | D45: =('DCF'!$D$97/A45)^(1/7)-1 | E45: =('DCF'!$D$97/A45)^(1/10)-1 | F45: ='DCF'!$D$97
A46: ='Assumptions'!$B$8*(1+-0.1) | B46: =('DCF'!$D$97/A46)^(1/3)-1 | C46: =('DCF'!$D$97/A46)^(1/5)-1 | D46: =('DCF'!$D$97/A46)^(1/7)-1 | E46: =('DCF'!$D$97/A46)^(1/10)-1 | F46: ='DCF'!$D$97
A47: ='Assumptions'!$B$8*(1+0.0) | B47: =('DCF'!$D$97/A47)^(1/3)-1 | C47: =('DCF'!$D$97/A47)^(1/5)-1 | D47: =('DCF'!$D$97/A47)^(1/7)-1 | E47: =('DCF'!$D$97/A47)^(1/10)-1 | F47: ='DCF'!$D$97
A48: ='Assumptions'!$B$8*(1+0.1) | B48: =('DCF'!$D$97/A48)^(1/3)-1 | C48: =('DCF'!$D$97/A48)^(1/5)-1 | D48: =('DCF'!$D$97/A48)^(1/7)-1 | E48: =('DCF'!$D$97/A48)^(1/10)-1 | F48: ='DCF'!$D$97
...

Sheet Returns_Multiple
A1: RETURNS — Market Multiple Exit
A3: Approach: B — Market Multiple Exit
A4: Multiple chosen: EV/EBITDA on FY30. Rationale: Mature profitable cash-flow generator → EBITDA multiple
A6: Peer comps (linked from Assumptions)
A7: Peer | B7: EV/NTM Rev | C7: NTM Rev CAGR | D7: NTM EBITDA Margin | E7: EV/NTM EBITDA
A8: Peer A | B8: 4.2 | C8: 0.14 | D8: 0.22 | E8: 19
A9: Peer B | B9: 3.5 | C9: 0.1 | D9: 0.18 | E9: 16.5
A10: Peer C | B10: 5.1 | C10: 0.18 | D10: 0.25 | E10: 21
A11: Peer D | B11: 2.8 | C11: 0.08 | D11: 0.16 | E11: 14
A13: Exit multiple range
B14: Bear | C14: Base | D14: Bull
A15: Multiple (EV/EBITDA, FY30) | B15: ='Assumptions'!$B$58 | C15: ='Assumptions'!$C$58 | D15: ='Assumptions'!$D$58
A16: EBITDA (FY30) | B16: ='DCF'!$H$21 | C16: ='DCF'!$H$24 | D16: ='DCF'!$H$27
A17: Implied EV at exit | B17: =B16*B15 | C17: =C16*C15 | D17: =D16*D15
A18: + Net Cash | B18: ='Assumptions'!$B$10 | C18: ='Assumptions'!$B$10 | D18: ='Assumptions'!$B$10
A19: Implied Equity Value | B19: =B17+B18 | C19: =C17+C18 | D19: =D17+D18
A20: Implied Exit Price | B20: =B19/'Assumptions'!$B$9 | C20: =C19/'Assumptions'!$B$9 | D20: =D19/'Assumptions'!$B$9
A22: IRR sensitivity (Base scenario)
A23: Entry ↓ / Exit multiple → | B23: =C15*(1+-0.3) | C23: =C15*(1+-0.15) | D23: =C15*(1+0.0) | E23: =C15*(1+0.14999999999999997) | F23: =C15*(1+0.3)
A24: (holding period assumed: 5y)
A25: ='Assumptions'!$B$8*(1+-0.3) | B25: =((C16*$B$23+'Assumptions'!$B$10)/'Assumptions'!$B$9/A25)^(1/5)-1 | C25: =((C16*$C$23+'Assumptions'!$B$10)/'Assumptions'!$B$9/A25)^(1/5)-1 | D25: =((C16*$D$23+'Assumptions'!$B$10)/'Assumptions'!$B$9/A25)^(1/5)-1 | E25: =((C16*$E$23+'Assumptions'!$B$10)/'Assumptions'!$B$9/A25)^(1/5)-1 | F25: =((C16*$F$23+'Assumptions'!$B$10)/'Assumptions'!$B$9/A25)^(1/5)-1
A26: ='Assumptions'!$B$8*(1+-0.2) | B26: =((C16*$B$23+'Assumptions'!$B$10)/'Assumptions'!$B$9/A26)^(1/5)-1 | C26: =((C16*$C$23+'Assumptions'!$B$10)/'Assumptions'!$B$9/A26)^(1/5)-1 | D26: =((C16*$D$23+'Assumptions'!$B$10)/'Assumptions'!$B$9/A26)^(1/5)-1 | E26: =((C16*$E$23+'Assumptions'!$B$10)/'Assumptions'!$B$9/A26)^(1/5)-1 | F26: =((C16*$F$23+'Assumptions'!$B$10)/'Assumptions'!$B$9/A26)^(1/5)-1
A27: ='Assumptions'!$B$8*(1+-0.1) | B27: =((C16*$B$23+'Assumptions'!$B$10)/'Assumptions'!$B$9/A27)^(1/5)-1 | C27: =((C16*$C$23+'Assumptions'!$B$10)/'Assumptions'!$B$9/A27)^(1/5)-1 | D27: =((C16*$D$23+'Assumptions'!$B$10)/'Assumptions'!$B$9/A27)^(1/5)-1 | E27: =((C16*$E$23+'Assumptions'!$B$10)/'Assumptions'!$B$9/A27)^(1/5)-1 | F27: =((C16*$F$23+'Assumptions'!$B$10)/'Assumptions'!$B$9/A27)^(1/5)-1
A28: ='Assumptions'!$B$8*(1+0.0) | B28: =((C16*$B$23+'Assumptions'!$B$10)/'Assumptions'!$B$9/A28)^(1/5)-1 | C28: =((C16*$C$23+'Assumptions'!$B$10)/'Assumptions'!$B$9/A28)^(1/5)-1 | D28: =((C16*$D$23+'Assumptions'!$B$10)/'Assumptions'!$B$9/A28)^(1/5)-1 | E28: =((C16*$E$23+'Assumptions'!$B$10)/'Assumptions'!$B$9/A28)^(1/5)-1 | F28: =((C16*$F$23+'Assumptions'!$B$10)/'Assumptions'!$B$9/A28)^(1/5)-1
A29: ='Assumptions'!$B$8*(1+0.1) | B29: =((C16*$B$23+'Assumptions'!$B$10)/'Assumptions'!$B$9/A29)^(1/5)-1 | C29: =((C16*$C$23+'Assumptions'!$B$10)/'Assumptions'!$B$9/A29)^(1/5)-1 | D29: =((C16*$D$23+'Assumptions'!$B$10)/'Assumptions'!$B$9/A29)^(1/5)-1 | E29: =((C16*$E$23+'Assumptions'!$B$10)/'Assumptions'!$B$9/A29)^(1/5)-1 | F29: =((C16*$F$23+'Assumptions'!$B$10)/'Assumptions'!$B$9/A29)^(1/5)-1
A30: ='Assumptions'!$B$8*(1+0.2) | B30: =((C16*$B$23+'Assumptions'!$B$10)/'Assumptions'!$B$9/A30)^(1/5)-1 | C30: =((C16*$C$23+'Assumptions'!$B$10)/'Assumptions'!$B$9/A30)^(1/5)-1 | D30: =((C16*$D$23+'Assumptions'!$B$10)/'Assumptions'!$B$9/A30)^(1/5)-1 | E30: =((C16*$E$23+'Assumptions'!$B$10)/'Assumptions'!$B$9/A30)^(1/5)-1 | F30: =((C16*$F$23+'Assumptions'!$B$10)/'Assumptions'!$B$9/A30)^(1/5)-1
A31: ='Assumptions'!$B$8*(1+0.3) | B31: =((C16*$B$23+'Assumptions'!$B$10)/'Assumptions'!$B$9/A31)^(1/5)-1 | C31: =((C16*$C$23+'Assumptions'!$B$10)/'Assumptions'!$B$9/A31)^(1/5)-1 | D31: =((C16*$D$23+'Assumptions'!$B$10)/'Assumptions'!$B$9/A31)^(1/5)-1 | E31: =((C16*$E$23+'Assumptions'!$B$10)/'Assumptions'!$B$9/A31)^(1/5)-1 | F31: =((C16*$F$23+'Assumptions'!$B$10)/'Assumptions'!$B$9/A31)^(1/5)-1
A33: Max entry for target IRR (Base multiple)
A34: Target IRR → | B34: 10% | C34: 15% | D34: 20% | E34: 25% | F34: 30%
A35: Max entry (5y holding) | B35: =C20/(1+0.1)^5 | C35: =C20/(1+0.15)^5 | D35: =C20/(1+0.2)^5 | E35: =C20/(1+0.25)^5 | F35: =C20/(1+0.3)^5
A37: SYNTHESIS — Approach A (DCF) vs B (Multiple)
B38: Bear | C38: Base | D38: Bull
A39: A) DCF intrinsic price | B39: ='DCF'!$B$97 | C39: ='DCF'!$C$97 | D39: ='DCF'!$D$97
A40: B) Multiple-based exit price | B40: =B20 | C40: =C20 | D40: =D20
A41: Upside vs CMP — A | B41: =B39/'Assumptions'!$B$8-1 | C41: =C39/'Assumptions'!$B$8-1 | D41: =D39/'Assumptions'!$B$8-1
A42: Upside vs CMP — B | B42: =B40/'Assumptions'!$B$8-1 | C42: =C40/'Assumptions'!$B$8-1 | D42: =D40/'Assumptions'!$B$8-1
A43: IRR at CMP (assumes 5y holding) — A | B43: =(B39/'Assumptions'!$B$8)^(1/5)-1 | C43: =(C39/'Assumptions'!$B$8)^(1/5)-1 | D43: =(D39/'Assumptions'!$B$8)^(1/5)-1
A44: IRR at CMP (assumes 5y holding) — B | B44: =(B40/'Assumptions'!$B$8)^(1/5)-1 | C44: =(C40/'Assumptions'!$B$8)^(1/5)-1 | D44: =(D40/'Assumptions'!$B$8)^(1/5)-1
